<?xml version="1.0"?>

<robot xmlns:xacro="http://ros.org/wiki/xacro">

  <!--File includes-->
  <xacro:include filename="$(find pal_gripper_description)/urdf/deg_to_rad.urdf.xacro" />
  <xacro:include filename="$(find pal_gripper_description)/urdf/gripper.transmission.xacro" />
  <xacro:include filename="$(find pal_gripper_description)/urdf/gripper.gazebo.xacro" />

  <xacro:property name="gripper_eps" value="0.001" />

  <xacro:macro name="pal_gripper" params="name parent *origin">

  <link name="${name}_tool_link">
    <inertial>
      <origin xyz="0 0 0" rpy="0 0 0" />
      <mass value="0.0001" />
      <inertia ixx="0.00001" ixy="0.0" ixz="0.0"
               iyy="0.00001" iyz="0.0"
               izz="0.00001" />
    </inertial>
  </link>

  <joint name="${name}_tool_joint" type="fixed">
    <xacro:insert_block name="origin"/>
    <parent link="${parent}" />
    <child link="${name}_tool_link" />
    <axis xyz="0 0 0" />
  </joint>

  <link name="${name}_link">
    <inertial>
      <origin rpy="0.0 0.0 0.0" xyz="-0.000294 0.000291 -0.033086" />
      <mass value="0.602660" />
      <inertia ixx="0.000693" ixy="0.000045" ixz="-0.000000"
               iyy="0.001024" iyz="0.000000"
               izz="0.000672" />
    </inertial>
    <visual>
      <origin rpy="0 0 0" xyz="0 0 0" />
      <geometry>
        <mesh filename="package://pal_gripper_description/meshes/gripper_link.stl"/>
      </geometry>
      <material name="White"/>
    </visual>
    <collision>
      <origin rpy="0 0 0" xyz="0 0 0" />
      <geometry>
        <mesh filename="package://pal_gripper_description/meshes/gripper_link_collision.stl"/>
      </geometry>
    </collision>
  </link>
  <gazebo reference="${name}_link">
    <material>Gazebo/White</material>
  </gazebo>

  <joint name="${name}_joint" type="fixed">
    <xacro:insert_block name="origin"/>
    <parent link="${parent}" />
    <child link="${name}_link" />
    <axis xyz="0 0 0" />
  </joint>

  <link name="${name}_right_finger_link">
    <inertial>
      <origin rpy="0 0 0" xyz="-0.004470 0.010766 -0.121013" />
      <mass value="0.109980" />
      <inertia ixx="0.000232" ixy="-0.000005" ixz="-0.000032"
               iyy="0.000224" iyz="0.000036"
               izz="0.000029" />
    </inertial>
    <visual>
      <origin rpy="0 0 3.1415" xyz="0 0 0" />
      <geometry>
        <mesh filename="package://pal_gripper_description/meshes/gripper_finger_link.stl" scale="-1 -1 1"/>
      </geometry>
      <material name="Black"/>
    </visual>
    <collision>
      <origin rpy="0 0 3.1415" xyz="0.005 0 -0.165" />
      <geometry>
        <box size="0.01 0.05 0.11"/>
      </geometry>
    </collision>
  </link>
  <gazebo reference="${name}_right_finger_link">
    <material>Gazebo/Black</material>
  </gazebo>

  <joint name="${name}_right_finger_joint" type="prismatic">
    <origin rpy="0 0 0" xyz="0. 0 0" />
    <parent link="${name}_link" />
    <child link="${name}_right_finger_link" />
    <axis xyz="1 0 0" />
    <limit effort="500" lower="0.0" upper="0.045" velocity="0.05" />
    <calibration rising="0.0" />
    <dynamics damping="80" />
    <safety_controller k_position="20"
                       k_velocity="20"
                       soft_lower_limit="${0.0 + gripper_eps}"
                       soft_upper_limit="${0.045 - gripper_eps}" />
  </joint>

  <link name="${name}_left_finger_link">
    <inertial>
      <origin rpy="0 0 0" xyz="-0.004470 0.010766 -0.121013" />
      <mass value="0.109980" />
      <inertia ixx="0.000232" ixy="-0.000005" ixz="-0.000032"
               iyy="0.000224" iyz="0.000036"
               izz="0.000029" />
    </inertial>
    <visual>
      <origin rpy="0 0 3.1415" xyz="0 0 0"/>
      <geometry>
        <mesh filename="package://pal_gripper_description/meshes/gripper_finger_link.stl"/>
      </geometry>
      <material name="Black"/>
    </visual>
    <collision>
      <origin rpy="0 0 3.1415" xyz="-0.005 0 -0.165" />
      <geometry>
        <box size="0.01 0.05 0.11"/>
      </geometry>
    </collision>
  </link>
  <gazebo reference="${name}_left_finger_link">
    <material>Gazebo/Black</material>
  </gazebo>

  <joint name="${name}_left_finger_joint" type="prismatic">
    <origin rpy="0 0 0" xyz="0. 0 0" />
    <parent link="${name}_link" />
    <child link="${name}_left_finger_link" />
    <axis xyz="-1 0 0" />
    <limit effort="500" lower="0" upper="0.045" velocity="0.05" />
    <calibration rising="0.0" />
    <dynamics damping="80" />
    <safety_controller k_position="20"
                       k_velocity="20"
                       soft_lower_limit="${0.0 + gripper_eps}"
                       soft_upper_limit="${0.045 - gripper_eps}" />
  </joint>

  <!-- Grasping frame -->
  <joint name="${name}_grasping_frame_joint" type="fixed">
    <parent link="${name}_link" />
    <child link="${name}_grasping_frame" />
    <origin xyz="0 0 -0.12" rpy="-1.5708 1.5708 0" />
  </joint>
  <link name="${name}_grasping_frame">
    <inertial>
      <origin xyz="0 0 0" rpy="0 0 0" />
      <mass value="0.0001" />
      <inertia ixx="0.00001" ixy="0.0" ixz="0.0"
               iyy="0.00001" iyz="0.0"
               izz="0.00001" />
    </inertial>
  </link>

  <xacro:gripper_simple_transmission name="${name}_left_finger" reduction="1.0"/>
  <xacro:gripper_simple_transmission name="${name}_right_finger" reduction="1.0"/>

  <xacro:finger_gazebo name="${name}_left_finger"/>
  <xacro:finger_gazebo name="${name}_right_finger"/>

 </xacro:macro>

</robot>
